* 在 Go 语言中，程序中一般是使用错误来处理异常情况。对于程序中出现的大部分异常情况，错误就已经够用了。
* 有些情况，当程序发生异常时，无法继续运行。在这种情况下，我们会使用 panic 来终止程序。当函数发生 panic 时，它会终止运行，在执行完所有的延迟函数后，程序控制返回到该函数的调用方。这样的过程会一直持续下去，直到当前协程的所有函数都返回退出，然后程序会打印出 panic 信息，接着打印出堆栈跟踪（Stack Trace），最后程序终止。.
* 当程序发生 panic 时，使用 recover 可以重新获得对该程序的控制。
* 可以认为 panic 和 recover 与其他语言中的 try-catch-finally 语句类似，只不过一般我们很少使用 panic 和 recover。你应该尽可能地使用错误，而不是使用 panic 和 recover。只有当程序不能继续运行的时候，才应该使用 panic 和 recover 机制。
* panic 有两个合理的用例。发生了一个不能恢复的错误，此时程序不能继续运行。发生了一个编程上的错误。

```go
package main

import (  
    "fmt"
)

func fullName(firstName *string, lastName *string) {
    if firstName == nil {
        // panic 的签名func panic(interface{})
        panic("runtime error: first name cannot be nil")
    }
    if lastName == nil {
        panic("runtime error: last name cannot be nil")
    }
    fmt.Printf("%s %s\n", *firstName, *lastName)
    fmt.Println("returned normally from fullName")
}

func main() {
    firstName := "Elon"
    fullName(&firstName, nil)
    fmt.Println("returned normally from main")
}
```
* 发生 panic 时的 defer
```go
package main

import (
    "fmt"
)

func fullName(firstName *string, lastName *string) {
    defer fmt.Println("deferred call in fullName")
    if firstName == nil {
        panic("runtime error: first name cannot be nil")
    }
    if lastName == nil {
        panic("runtime error: last name cannot be nil")
    }
    fmt.Printf("%s %s\n", *firstName, *lastName)
    fmt.Println("returned normally from fullName")
}

func main() {
    defer fmt.Println("deferred call in main")
    firstName := "Elon"
    fullName(&firstName, nil)
    fmt.Println("returned normally from main")
}
```
* recover 是一个内建函数，用于重新获得 panic 协程的控制。
* 只有在延迟函数的内部，调用 recover 才有用。
```go
package main

import (
    "fmt"
)

func recoverName() {
    if r := recover(); r!= nil {    // recover()，返回了调用 panic 的传参。
        fmt.Println("recovered from ", r)
    }
}

func fullName(firstName *string, lastName *string) {
    defer recoverName()
    if firstName == nil {
        panic("runtime error: first name cannot be nil")
    }
    if lastName == nil {
        panic("runtime error: last name cannot be nil")
    }
    fmt.Printf("%s %s\n", *firstName, *lastName)
    fmt.Println("returned normally from fullName")
}

func main() {
    defer fmt.Println("deferred call in main")
    firstName := "Elon"
    fullName(&firstName, nil)
    fmt.Println("returned normally from main")
}
```
* 只有在相同的 Go 协程中调用 recover 才管用。recover 不能恢复一个不同协程的 panic。
```go
package main

import (
    "fmt"
    "time"
)

func recovery() {
    if r := recover(); r != nil {
        fmt.Println("recovered:", r)
    }
}

func a() {
    defer recovery()    // 调用 recovery 的协程和 b() 中发生 panic 的协程并不相同，因此不可能恢复 panic。
    fmt.Println("Inside A")
    go b()
    time.Sleep(1 * time.Second)
}

func b() {
    fmt.Println("Inside B")
    panic("oh! B panicked")
}

func main() {
    a()
    fmt.Println("normally returned from main")
}
```
* 运行时错误（如数组越界）也会导致 panic。这等价于调用了内置函数 panic，其参数由接口类型 runtime.Error 给出。
* 是否可以恢复一个运行时 panic？当然可以！
```go
package main

import (
    "fmt"
)

func r() {
    if r := recover(); r != nil {
        fmt.Println("Recovered", r)
    }
}

func a() {
    defer r()
    n := []int{5, 7, 4}
    fmt.Println(n[3])
    fmt.Println("normally returned from a")
}

func main() {
    a()
    fmt.Println("normally returned from main")
}
```
* 在上述程序里，恢复 panic 之后，我们就失去了堆栈跟踪。有办法可以打印出堆栈跟踪，就是使用 Debug 包中的 PrintStack 函数。
```go
package main

import (
    "fmt"
    "runtime/debug"
)

func r() {
    if r := recover(); r != nil {
        fmt.Println("Recovered", r)
        debug.PrintStack()
    }
}

func a() {
    defer r()
    n := []int{5, 7, 4}
    fmt.Println(n[3])
    fmt.Println("normally returned from a")
}

func main() {
    a()
    fmt.Println("normally returned from main")
}
```
